Workbook

Sheet Queries
A1: KEEP | B1: query_code | C1: query_text | D1: category | E1: stage | F1: specificity | G1: persona | H1: study_pattern | I1: subscription_state | J1: status | K1: expected_incentive | L1: soa_focus | M1: rationale
A2: y | B2: BC_AWA_BRD_NFP_01 | C2: my newborn keeps soaking through his diaper every night, what am I doing wrong? | D2: Baby Care | E2: Awareness | F2: Broad | G2: New / First-Time Parent | H2: brand_vs_brand | J2: Active | K2: Low | L2: Mention Rate, SoA% | M2: Problem-recognition entry; tests whether Pampers surfaces unprompted before any brand or price intent.
A3: y | B3: BC_AWA_BRD_NFP_02 | C3: how do I figure out what diaper size my baby actually needs? | D3: Baby Care | E3: Awareness | F3: Broad | G3: New / First-Time Parent | H3: brand_vs_brand | J3: Active | K3: Low | L3: Mention Rate | M3: Sizing-help query; educational intent, no price expected — calibration for the Low flag.
A4: y | B4: BC_AWA_BRD_NFP_03 | C4: first-time dad here — what diapers do I even need for a newborn? | D4: Baby Care | E4: Awareness | F4: Broad | G4: New / First-Time Parent | H4: brand_vs_brand | J4: Active | K4: Low | L4: Mention Rate, RSI | M4: Zero-knowledge stage; tests the agent's default brand recommendation.
A5: y | B5: BC_AWA_BRD_SSP_01 | C5: my baby gets a red rash from her diapers, is that normal? | D5: Baby Care | E5: Awareness | F5: Broad | G5: Sensitive-Skin Baby Parent | H5: brand_vs_brand | J5: Active | K5: Low | L5: Mention Rate, SoA% | M5: Symptom-driven; whether Pampers (Sensitive/Pure) surfaces as a solution unprompted.
A6: y | B6: BC_AWA_BRD_NFP_04 | C6: how many diapers a day does a newborn go through? | D6: Baby Care | E6: Awareness | F6: Broad | G6: New / First-Time Parent | H6: brand_vs_brand | J6: Active | K6: Low | L6: Mention Rate | M6: Pure info; price here would be out of place — a clean expectation-Low control.
A7: y | B7: BC_AWA_BRD_ECP_01 | C7: are disposable diapers bad for the environment? | D7: Baby Care | E7: Awareness | F7: Broad | G7: Eco-Conscious Parent | H7: brand_vs_brand | J7: Active | K7: Low | L7: Mention Rate, SoA% | M7: Values-driven entry; whether eco framing pulls in Pampers Pure vs Honest/Coterie.
A8: y | B8: BC_AWA_BRD_NFP_05 | C8: what's the difference between newborn and size 1 diapers? | D8: Baby Care | E8: Awareness | F8: Broad | G8: New / First-Time Parent | H8: brand_vs_brand | J8: Active | K8: Low | L8: Mention Rate | M8: Educational; tests brand mention inside a purely informational answer.
A9: y | B9: BC_AWA_BRD_SSP_02 | C9: diaper blowouts every morning — how do people deal with this? | D9: Baby Care | E9: Awareness | F9: Broad | G9: Sensitive-Skin Baby Parent | H9: brand_vs_brand | J9: Active | K9: Low | L9: Mention Rate, RSI | M9: Fit/absorbency problem-solving; no price expected.
A10: y | B10: BC_RES_BRD_SSP_03 | C10: what are the gentlest diapers for a baby with really sensitive skin? | D10: Baby Care | E10: Research | F10: Broad | G10: Sensitive-Skin Baby Parent | H10: brand_vs_brand | J10: Active | K10: Low | L10: Mention Rate, RSI | M10: Core attribute discovery; Pampers Pure/Sensitive vs Huggies Special Delivery/Honest.
A11: y | B11: BC_RES_MID_SSP_04 | C11: are 'sensitive' diapers actually different or just marketing? | D11: Baby Care | E11: Research | F11: Mid | G11: Sensitive-Skin Baby Parent | H11: brand_vs_brand | J11: Active | K11: Low | L11: Mention Rate, SoA% | M11: Skeptical research; tests whether Pampers Pure/Sensitive is named and defended.
A12: y | B12: BC_RES_BRD_ECP_02 | C12: what are the most eco-friendly disposable diapers? | D12: Baby Care | E12: Research | F12: Broad | G12: Eco-Conscious Parent | H12: brand_vs_brand | J12: Active | K12: Low | L12: Mention Rate, SoA% | M12: Eco share-of-voice; where Pampers Pure competes with Honest/Coterie/Bambo.
A13: y | B13: BC_RES_MID_ECP_03 | C13: which diaper brands are actually free of fragrances and lotions? | D13: Baby Care | E13: Research | F13: Mid | G13: Eco-Conscious Parent | H13: brand_vs_brand | J13: Active | K13: Low | L13: Mention Rate, RSI | M13: Ingredient-driven; attribute accuracy for Pampers Pure.
... A27: y | B27: BC_CMP_MID_ECP_05 | C27: Pampers Pure vs Honest Company diapers — which is better and cheaper? | D27: Baby Care | E27: Comparison | F27: Mid | G27: Eco-Conscious Parent | H27: brand_vs_brand | J27: Active | K27: High | L27: Net-Price presence, RSI | M27: Eco head-to-head with an explicit 'cheaper' — price expected.
A28: y | B28: BC_CMP_MID_SRP_01 | C28: is it worth subscribing to diapers or just buying them as I go? | D28: Baby Care | E28: Comparison | F28: Mid | G28: Subscription / Replenishment Parent | H28: brand_at_retail | I28: not_subscribed | J28: Active | K28: High | L28: Subscription-offer presence, Net-Price presence | M28: Subscription-value question; expects S&S / auto-ship economics.
A29: y | B29: BC_CMP_MID_VCP_06 | C29: are the big Costco boxes of diapers actually cheaper than Pampers on Amazon? | D29: Baby Care | E29: Comparison | F29: Mid | G29: Value-Conscious Parent | H29: brand_at_retail | J29: Active | K29: High | L29: Net-Price presence, Deal Citation | M29: Cross-retailer value; expects a real price comparison.
A30: y | B30: BC_CMP_MID_SSP_08 | C30: Pampers Sensitive vs Huggies Special Delivery for eczema-prone skin? | D30: Baby Care | E30: Comparison | F30: Mid | G30: Sensitive-Skin Baby Parent | H30: brand_vs_brand | J30: Active | K30: Mixed | L30: RSI, Mention Rate | M30: Premium-sensitive head-to-head; attribute-led, value secondary.
A31: y | B31: BC_CMP_MID_NFP_10 | C31: what's the difference between Pampers Swaddlers, Baby-Dry, and Cruisers? | D31: Baby Care | E31: Comparison | F31: Mid | G31: New / First-Time Parent | H31: brand_vs_brand | J31: Active | K31: Low | L31: Mention Rate, RSI | M31: Within-brand line education; expectation-Low even at Comparison — a calibration point.
A32: y | B32: BC_CMP_MID_VCP_07 | C32: generic vs Pampers diapers — is the price difference worth the quality? | D32: Baby Care | E32: Comparison | F32: Mid | G32: Value-Conscious Parent | H32: brand_vs_brand | J32: Active | K32: High | L32: Net-Price presence, RSI | M32: Value-vs-quality; explicitly invokes the price difference.
A33: y | B33: BC_CMP_MID_ECP_06 | C33: which is the better value, Pampers Pure or Coterie? | D33: Baby Care | E33: Comparison | F33: Mid | G33: Eco-Conscious Parent | H33: brand_vs_brand | J33: Active | K33: High | L33: Net-Price presence | M33: Premium-eco value comparison; expects price context.
A34: y | B34: BC_CMP_MID_SRP_02 | C34: is Amazon Subscribe & Save or Target's diaper deals a better way to save on Pampers? | D34: Baby Care | E34: Comparison | F34: Mid | G34: Subscription / Replenishment Parent | H34: brand_at_retail | I34: not_subscribed | J34: Active | K34: High | L34: Subscription-offer presence, Deal Citation, Member-price presence | M34: Program-vs-program value; directly targets incentive surfacing.
A35: y | B35: BC_CMP_MID_SSP_09 | C35: do more expensive diapers actually prevent diaper rash better? | D35: Baby Care | E35: Comparison | F35: Mid | G35: Sensitive-Skin Baby Parent | H35: brand_vs_brand | J35: Active | K35: Mixed | L35: RSI, Net-Price presence | M35: Price-quality attribute; genuinely mixed expectation.
A36: y | B36: BC_CMP_MID_VCP_08 | C36: how do I compare the real cost per diaper between brands? | D36: Baby Care | E36: Comparison | F36: Mid | G36: Value-Conscious Parent | H36: brand_vs_brand | J36: Active | K36: High | L36: Net-Price presence | M36: Cost-per-unit method; strongly expects price math.
A37: y | B37: BC_CMP_MID_NFP_11 | C37: everyone recommends Pampers or Huggies — how do I actually pick? | D37: Baby Care | E37: Comparison | F37: Mid | G37: New / First-Time Parent | H37: brand_vs_brand | J37: Active | K37: Mixed | L37: RSI, SoA% | M37: Tie-breaker; whether value is offered as the deciding factor.
A38: y | B38: BC_CMP_MID_ECP_07 | C38: are eco-friendly diapers like Pampers Pure a lot more expensive than regular ones? | D38: Baby Care | E38: Comparison | F38: Mid | G38: Eco-Conscious Parent | H38: brand_vs_brand | J38: Active | K38: High | L38: Net-Price presence | M38: Eco price-premium; expects a price delta.
A39: y | B39: BC_CMP_MID_SRP_03 | C39: if I set up auto-delivery for Pampers, do I actually save money? | D39: Baby Care | E39: Comparison | F39: Mid | G39: Subscription / Replenishment Parent | H39: brand_at_retail | I39: not_subscribed | J39: Active | K39: High | L39: Subscription-offer presence, Net-Price presence | M39: Subscription payoff; expects the S&S discount surfaced.
A40: y | B40: BC_RTB_NAR_VCP_09 | C40: cheapest place to buy Pampers Swaddlers size 3 right now? | D40: Baby Care | E40: Ready to Buy | F40: Narrow | G40: Value-Conscious Parent | H40: brand_at_retail | J40: Active | K40: High | L40: Net-Price presence, Deal Citation | M40: Canonical price-seeking; expects retailer + price.
A41: y | B41: BC_RTB_NAR_SRP_04 | C41: is it cheaper to subscribe to Pampers on Amazon or just buy them at Target? | D41: Baby Care | E41: Ready to Buy | F41: Narrow | G41: Subscription / Replenishment Parent | H41: brand_at_retail | I41: not_subscribed | J41: Active | K41: High | L41: Subscription-offer presence, Net-Price presence, Member-price presence | M41: Cross-retailer subscription value — the exact gap from the case study.
A42: y | B42: BC_RTB_NAR_VCP_10 | C42: any good deals or coupons on Pampers Swaddlers this week? | D42: Baby Care | E42: Ready to Buy | F42: Narrow | G42: Value-Conscious Parent | H42: brand_at_retail | J42: Active | K42: High | L42: Deal Citation, Net-Price presence | M42: Coupon-seeking; directly tests deal_cited.
A43: y | B43: BC_RTB_NAR_SRP_05 | C43: how much do I save with Subscribe & Save on Pampers Pure? | D43: Baby Care | E43: Ready to Buy | F43: Narrow | G43: Subscription / Replenishment Parent | H43: brand_at_retail | I43: subscribed | J43: Active | K43: High | L43: Subscription-offer presence, Net-Price presence | M43: Quantified S&S expectation.
A44: y | B44: BC_RTB_NAR_VCP_11 | C44: where can I get the best price on a big box of Pampers size 4? | D44: Baby Care | E44: Ready to Buy | F44: Narrow | G44: Value-Conscious Parent | H44: brand_at_retail | J44: Active | K44: High | L44: Net-Price presence, Deal Citation | M44: Bulk price-seeking; expects retailer + per-unit.
A45: y | B45: BC_RTB_NAR_SRP_06 | C45: does Target Circle or Walmart give a better deal on Pampers? | D45: Baby Care | E45: Ready to Buy | F45: Narrow | G45: Subscription / Replenishment Parent | H45: brand_at_retail | J45: Active | K45: High | L45: Member-price presence, Deal Citation | M45: Loyalty-program value — tests member-price surfacing (the layer agents miss).
A46: y | B46: BC_RTB_NAR_VCP_12 | C46: is there a discount if I buy Pampers in bulk? | D46: Baby Care | E46: Ready to Buy | F46: Narrow | G46: Value-Conscious Parent | H46: brand_at_retail | J46: Active | K46: High | L46: Deal Citation, Net-Price presence | M46: Basket/bulk discount; tests basket-deal surfacing (the Target $30-GC type).
A47: y | B47: BC_RTB_NAR_SSP_10 | C47: cheapest place to buy Pampers Sensitive size 2? | D47: Baby Care | E47: Ready to Buy | F47: Narrow | G47: Sensitive-Skin Baby Parent | H47: brand_at_retail | J47: Active | K47: High | L47: Net-Price presence | M47: Sensitive-SKU price-seeking; attribute + price combined.
A48: y | B48: BC_RTB_NAR_VCP_13 | C48: what's the current price of Pampers Swaddlers 164 count at Walmart? | D48: Baby Care | E48: Ready to Buy | F48: Narrow | G48: Value-Conscious Parent | H48: brand_at_retail | J48: Active | K48: High | L48: Net-Price presence | M48: Exact-SKU price lookup — the Walmart control case (should surface correctly).
A49: y | B49: BC_RTB_NAR_SRP_07 | C49: set me up with the cheapest recurring diaper delivery for Pampers | D49: Baby Care | E49: Ready to Buy | F49: Narrow | G49: Subscription / Replenishment Parent | H49: brand_at_retail | I49: not_subscribed | J49: Active | K49: High | L49: Subscription-offer presence, Net-Price presence | M49: Action-oriented subscription; expects auto-ship pricing.
A50: y | B50: BC_RTB_NAR_VCP_14 | C50: are Pampers cheaper on Amazon or at Target today? | D50: Baby Care | E50: Ready to Buy | F50: Narrow | G50: Value-Conscious Parent | H50: brand_at_retail | J50: Active | K50: High | L50: Net-Price presence | M50: Cross-retailer spot price; expects a live comparison.
A51: y | B51: BC_RTB_NAR_ECP_08 | C51: best price on Pampers Pure size 1? | D51: Baby Care | E51: Ready to Buy | F51: Narrow | G51: Eco-Conscious Parent | H51: brand_at_retail | J51: Active | K51: High | L51: Net-Price presence, Deal Citation | M51: Eco-SKU price-seeking.
A52: y | B52: BC_RTB_NAR_VCP_15 | C52: how much is a month's supply of Pampers for a size 3 baby? | D52: Baby Care | E52: Ready to Buy | F52: Narrow | G52: Value-Conscious Parent | H52: brand_at_retail | J52: Active | K52: High | L52: Net-Price presence | M52: Cost-to-replenish; expects total / monthly math.
A53: y | B53: BC_RTB_NAR_SRP_08 | C53: if I subscribe to Pampers, can I still use coupons on top? | D53: Baby Care | E53: Ready to Buy | F53: Narrow | G53: Subscription / Replenishment Parent | H53: brand_at_retail | I53: subscribed | J53: Active | K53: High | L53: Deal Citation, Subscription-offer presence | M53: Stacking question; tests whether the agent understands combined incentives.
...

Sheet Summary
A1: Baby Care — Persona / Funnel Price-Promo-Expectation Study
A2: Query set for review. Set KEEP=n on the Queries tab to cut a row; counts below update live.
A4: By funnel stage
A5: Value | B5: All | C5: Kept
A6: Awareness | B6: =COUNTIF(Queries!E:E,A6) -> 8 | C6: =COUNTIFS(Queries!E:E,A6,Queries!$A:$A,"y") -> 8
A7: Research | B7: =COUNTIF(Queries!E:E,A7) -> 12 | C7: =COUNTIFS(Queries!E:E,A7,Queries!$A:$A,"y") -> 12
A8: Comparison | B8: =COUNTIF(Queries!E:E,A8) -> 18 | C8: =COUNTIFS(Queries!E:E,A8,Queries!$A:$A,"y") -> 18
A9: Ready to Buy | B9: =COUNTIF(Queries!E:E,A9) -> 17 | C9: =COUNTIFS(Queries!E:E,A9,Queries!$A:$A,"y") -> 17
A10: Total | B10: =SUM(B6:B9) -> 55 | C10: =SUM(C6:C9) -> 55
A12: By expected-incentive
A13: Value | B13: All | C13: Kept
A14: Low | B14: =COUNTIF(Queries!K:K,A14) -> 18 | C14: =COUNTIFS(Queries!K:K,A14,Queries!$A:$A,"y") -> 18
A15: Mixed | B15: =COUNTIF(Queries!K:K,A15) -> 9 | C15: =COUNTIFS(Queries!K:K,A15,Queries!$A:$A,"y") -> 9
A16: High | B16: =COUNTIF(Queries!K:K,A16) -> 28 | C16: =COUNTIFS(Queries!K:K,A16,Queries!$A:$A,"y") -> 28
A17: Total | B17: =SUM(B14:B16) -> 55 | C17: =SUM(C14:C16) -> 55
A19: By persona
A20: Value | B20: All | C20: Kept
A21: New / First-Time Parent | B21: =COUNTIF(Queries!G:G,A21) -> 11 | C21: =COUNTIFS(Queries!G:G,A21,Queries!$A:$A,"y") -> 11
A22: Value-Conscious Parent | B22: =COUNTIF(Queries!G:G,A22) -> 17 | C22: =COUNTIFS(Queries!G:G,A22,Queries!$A:$A,"y") -> 17
A23: Sensitive-Skin Baby Parent | B23: =COUNTIF(Queries!G:G,A23) -> 10 | C23: =COUNTIFS(Queries!G:G,A23,Queries!$A:$A,"y") -> 10
A24: Subscription / Replenishment Parent | B24: =COUNTIF(Queries!G:G,A24) -> 9 | C24: =COUNTIFS(Queries!G:G,A24,Queries!$A:$A,"y") -> 9
A25: Eco-Conscious Parent | B25: =COUNTIF(Queries!G:G,A25) -> 8 | C25: =COUNTIFS(Queries!G:G,A25,Queries!$A:$A,"y") -> 8
A26: Total | B26: =SUM(B21:B25) -> 55 | C26: =SUM(C21:C25) -> 55
